Workbook
Name APE: '[1]MP&Result'!$C$17

Sheet Perbandingan Fitur
E1: Q3 2025 | F1: Q3 2025 | H1: Q3 2025
B2: Perusahaan Asuransi | C2: BCA Life | D2: AIA | E2: Prudential | F2: Sun Life | G2: Manulife | H2: Manulife | I2: Allianz | J2: AXA | K2: Allianz | L2: Manulife | M2: SunLife | N2: Allianz
B3: Nama Produk | C3: Heritage Platinum Protection (Heritage+) | D3: Wealth Premier Protection (Premier Pro) | E3: PRUInfinity | F3: Sun Proteksi Heritage 100 | G3: MiTreasure Whole Life Legacy | H3: Manulife Protection Optimum Elite (PRIME) | I3: Premier Heritage Assurance | J3: AXA Future Protector | K3: Allianz Legacy Pro | L3: Manulife Dynamic Life Assurance | M3: X-Tra Proteksi Waris USD | N3: AlliSya Legacy Max
B4: Tipe Produk | C4: Tradisional Seumur Hidup | D4: Tradisional Seumur Hidup | E4: Tradisional Seumur Hidup | F4: Tradisional Seumur Hidup | G4: Tradisional Seumur Hidup | H4: Tradisional Seumur Hidup | I4: Tradisional Seumur Hidup | K4: Tradisional Seumur Hidup | L4: Asuransi Dwiguna | M4: Asuransi Seumur Hidup | N4: Asuransi Jiwa Dwiguna Kombinasi
B5: Jalur Distribusi | C5: Bancassurance - BCA | D5: Bancassurance - BCA | E5: Bancassurance - UOB | F5: Agency | G5: Bancassurance - DBS | H5: Bancassurance - DBS | I5: Bancassurance - HSBC | K5: Agency | L5: Agency | N5: Agency, Direct Marketing
B6: Masa Pertanggungan | C6: Hingga Tertanggung berusia 99 tahun | D6: Hingga Tertanggung berusia 99 tahun | E6: Hingga Tertanggung berusia 100 tahun | F6: Hingga Tertanggung berusia 100 tahun | G6: Hingga Tertanggung berusia 99 tahun | H6: Plan A: hingga Tertanggung berusia 75 tahun Plan B: hingga Tertanggung 100 tahun | I6: Hingga Tertanggung berusia 100 tahun | K6: Hingga Tertanggung berusia 100 tahun | L6: Plan A: 20/30 tahun Plan B: 20/30/40/50/60 tahun Plan C: 20/30/40/50/60/70/80/90 tahun | M6: Seumur hidup/Hingga Tertanggung mencapai Usia 100 tahun | N6: Hingga Tertanggung berusia 120 tahun
B7: Masa Pembayaran Premi | C7: Sekaligus, Berkala (2,5,10,15) tahun | D7: Sekaligus, Berkala (2,5,10) tahun | E7: 3 atau 6 tahun | F7: 5 atau 10 tahun | G7: 5 atau 10 tahun | H7: Sekaligus, berkala (3 atau 5) tahun | I7: 3 tahun | K7: 5,10,15 tahun | L7: 5/10/15/20 tahun | M7: Sekaligus dan 5 thun | N7: Sekaligus, 5, 10, atau 15 tahun
B8: Frekuensi Pembayaran Premi | C8: Sekaligus, Bulanan, Kuartalan, Semesteran, Tahunan | D8: Sekaligus, Bulanan, Kuartalan, Semesteran, Tahunan | E8: Bulanan, Kuartalan, Semesteran, Tahunan | F8: Bulanan, Kuartalan, Semesteran, Tahunan | G8: Bulanan, Kuartalan, Semesteran, Tahunan | H8: Bulanan, Kuartalan, Semesteran, Tahunan | I8: Bulanan, Kuartalan, Semesteran, Tahunan | K8: Bulanan, Kuartalan, Semesteran, Tahunan | L8: Tahunan, Semester, Kuartalan, dan Bulanan | M8: Tahunan, Semester, Kuartalan, dan Bulanan | N8: Tahunan
B9: Minimum Premi | C9: Min. Rp4.515.000 / USD505,75 per tahun | D9: Min. Rp100 mio / tahun | E9: 3 tahun: Min. Rp200 mio / tahun 6 tahun: Min. Rp150 mio/tahun | F9: Min Rp3.600.000 / tahun | G9: Min. Rp50 mio / tahun | H9: Min. Rp11.400.000 /USD1.080 per bulan | I9: Min. Rp100 mio / USD10.000 per tahun | K9: No Info | N9: No Info
B10: Minimum UP | C10: Rp500 mio | D10: Rp 2 bio | E10: Rp 3 bio | F10: Rp 200 mio | H10: No info | I10: berupa ROP | K10: Rp200 mio / USD20.000 | L10: Rp 100 mio | M10: ditentukan berdasarkan Premi Tahunan yang dipilih pada saat pengajuan asuransi | N10: Rp 200 mio
B11: Usia Masuk | C11: 6 bulan - 70 tahun | D11: - MPP Sekaligus, 2, 5 tahun: 18 - 70 tahun - MPP 10 tahun: 18 - 60 tahun | E11: - PP Individu: 18 - 70 tahun - PP Perusahaan: 19 - 70 tahun | F11: 30 hari - 70 tahun | G11: 18 - 70 tahun | H11: Plan A: 30 hari - 55 tahun Plan B: 30 hari - 70 tahun | I11: 1 bulan - 70 tahun | K11: MPP 5 - 10 tahun: 1 bulan - 70 tahun MPP 15 tahun: 1 bulan - 59 tahun | L11: Minimum: 30 hari Maksimum: Mana yang lebih kecil antara 70 atau 110 tahun dikurangi Masa Pertanggungan | M11: Tertanggung: 30 hari - 70 tahun Tertanggung Manfaat Pembebasan Premi: 18 - 70 tahun | N11: - MPP Sekaligus atau 5 tahun: 1 bulan - 70 tahun - MPP 10 tahun: 1 bulan - 65 tahun - MPP 15 tahun: 1 bulan - 59 tahun
B12: Mata Uang | C12: Rupiah dan USD | D12: Rupiah | E12: Rupiah | F12: Rupiah | H12: Rupiah dan USD | I12: Rupiah dan USD | K12: Rupiah dan USD | L12: Rupiah (IDR) | M12: USD | N12: Rupiah
B13: Masa Tunggu | C13: Tidak ada | E13: Tidak ada | F13: Tidak ada | H13: Tidak ada | K13: Tidak ada | N13: Tidak ada
B14: Underwriting | C14: Full UW | D14: Full UW | E14: Full UW | F14: Full UW | G14: Full UW | H14: SIO: untuk Usia ≤ 60 tahun dengan UP ≤ 5 bio / USD500.000 Full UW: - seluruh Usia dengan UP > Rp 5 bio / USD500.000 - Usia Tertanggung > 60 tahun dgn UP ≤ Rp 5 bio / USD500.000 - Jika PP memilih Pertanggungan Tambahan | I14: GIO: - Usia Masuk ≤ 65 tahun dengan batasan UW Rp1,5 bio / USD115.000 SIO: - Usia Masuk > 65 tahun dengan batasan UW Rp1,5 bio / USD115.000; atau - Usia Masuk ≤ 60 tahun dengan batasan UW > Rp5 bio / USD380.000 Full UW: - Usia Masuk > 60 tahun dengan batasan UW h> Rp5 bio / USD380.000 - Semua Usia Masuk dengan batasan UW > Rp5 bio/ USD380.000 | K14: Full UW | L14: Full UW | M14: Full UW | N14: Full UW
A15: Manfaat Asuransi
B16: Plan | C16: Essential: tanpa Manfaat Hidup | D16: Elevate: tanpa Manfaat Hidup | E16: N/A | F16: Plan 5: MPP 5 tahun | G16: N/A | H16: Plan A: hingga Tertanggung berusia 75 tahun | I16: Plan Heritage Prime: berupa ROP | K16: N/A | L16: Plan A, Plan B, Plan C (dibedakan berdasarkan Masa Pertanggungan dan Manfaat Maturity) | M16: Plan Prime, Plan Signature, Plan Excellence | N16: Tidak ada
C17: Secure: dengan Manfaat Hidup | D17: Viva: dengan Manfaat Hidup | F17: Plan 10: MPP 10 tahun | H17: Plan B: hingga Tertanggung 100 tahun | I17: Plan Heritage Infinite: berupa Nilai Tunai
B18: Manfaat Meninggal Dunia karena Sebab Apapun | C18: UP hingga 200% UP (kenaikan UP 25% per 5 tahun) dikurangi Manfaat Hidup dan Manfaat TI yang sudah dibayarkan (jika ada) | D18: 100% UP + booster UP (booster UP berupa kenaikan UP 10% tiap 3 tahun hingga 200% UP) | E18: 100% UP + booster UP dikurangi Manfaat Tunai | F18: 100% UP | G18: 100% UP dikurangi Manfaat Pembayaran Tunai (jika ada) | H18: Plan A: ulang tahun Polis ke- - < 10: 100% UP - ≥ 10 - akhir masa pertanggungan: 150% UP | I18: Plan Heritage Prime: 105% ROP + Nilai Tambahan Manfaat Meninggal Dunia (jika ada) | K18: 100% UP + booster UP pada saat Tertanggung mencapai Usia 75 tahun | L18: 100% UP dan selanjutnya Polis berakhir | M18: 100% UP + Terminal Bonus (jika ada), dan Manfaat Booster UP: booster 70% UP dibayarkan saat Tertanggung Meninggal Dunia. (hanya tersedia di Plan Signature) Manfaat Tambahan Uang Pertanggungan: UP Meningkat sebesar - Plan Prime: - Plan Excellence: peningkatan UP sebesar 1% setiap dua tahun dimulai dari tahun polis ke-3 - Plan Signature: peningkatan UP sebesar 3% setiap tahun dimulai dari tahun polis ke-26 Note: Terminal Bonus adalah bonus berupa nilai tunai tidak dijamin yang diberikan Penanggung. | N18: 100% UP Booster UP: - penambahan sebesar 10% UP setiap 10 tahun Polis - dimulai dari awal Tahun Polis ke-15 atau Tahun Polis ke-25 (bergantung pada Usia Pihak Yang Diasuransi pada Tanggal Polis Mulai berlaku), maksimum 50% UP
E19: Manfaat Booster UP (peningkatan UP) - booster UP diberikan setiap ulang tahun Polis mulai Ulang Tahun Polis ke-5 - khusus Tahun Polis ke - 5: 15% UP - Tahun Polis ke-6 hingga seterusnya: 5% UP (per tahun) - Maksimum booster 150% UP (total maks UP 250%) | H19: Plan B: ulang tahun Polis ke- - < 10: 100% UP - ≥ 10 - < 25 : 150% UP - ≥ 25 - akhir masa pertanggungan: 200% UP | I19: Plan Heritage Infinite: Manfaat Pembayaran Tunai dijamin + Nilai Tambahan Manfaat Meninggal Dunia (jika ada) | K19: ketentuan booster UP: - +50% UP apabila Pemegang Polis memenuhi seluruh kriteria Persyaratan booster - +25% UP apabila Pemegang Polis tidak memenuhi salah satu kriteria Persyaratan booster
B20: Manfaat Tambahan Meninggal Dunia karena Kecelakaan | C20: tambahan 100% UP awal | D20: tambahan 100% UP awal | E20: N/A | F20: N/A | G20: N/A | H20: N/A | I20: N/A | K20: N/A | L20: N/A | M20: N/A | N20: N/A
B21: Manfaat Tambahan Meninggal Dunia karena Kecelakaan di Transportasi Umum di Indonesia | C21: N/A | D21: tambahan 150% UP awal | E21: N/A | F21: N/A | G21: N/A | H21: N/A | I21: Tambahan berupa: - hingga Usia 70 tahun: 100% ROP - > 70 tahun: 70% ROP | K21: N/A | L21: N/A | M21: N/A | N21: N/A
B22: Manfaat Terminal Illness | C22: 20% UP hingga maks. Rp3 bio | D22: N/A | E22: N/A | F22: N/A | G22: N/A | H22: N/A | I22: N/A | K22: N/A | L22: N/A | M22: N/A | N22: N/A
B23: Manfaat Hidup | C23: 50% ROP (dibayarkan pada Tahun Polis ke-15 atau Usia Tertanggung 60 tahun, mana yang lebih akhir) | D23: 25% UP (dibayarkan pada Tahun Polis ke-17 atau Usia Tertanggung 61 tahun, mana yang lebih akhir) | E23: Manfaat Tunai dibayarkan pada akhir tahun Polis ke-15 atau usia Tertanggung mencapai 65 tahun, mana yang paling akhir sebesar: | F23: Sun Golden 75: dibayarkan apabila Tertanggung hidup hingga usia 75 | G23: Jika masih hidup hingga Usia 70 tahun, akan mendapatkan Manfaat Pembayaran Tunai sebesar 20% UP | H23: N/A | I23: N/A | K23: N/A | L23: N/A | M23: Manfaat Hidup (khusus Plan Excellence): - Manfaat Longevity Reward: 20% UP pada saat Tertanggung mencapai Usia 65 tahun atau akhir tahun Polis ke-20, mana yang terjadi paling akhir.
B24: Manfaat Pemeriksaan Kesehatan | C24: Rp 2 mio / USD 125 | D24: AIA Program | E24: N/A | F24: N/A | G24: N/A | H24: N/A | I24: N/A | K24: N/A | L24: N/A | M24: N/A
B25: Manfaat Akhir Masa Pertanggungan | C25: 200% UP dikurangi Manfaat Hidup dan manfaat TI yang sudah dibayarkan (jika ada) | D25: 100% UP + booster UP terbentuk | E25: 100% UP + booster UP dikurangi Manfaat Tunai | F25: 100% UP | G25: 100% UP dikurangi Manfaat Pembayaran Tunai (jika ada) | H25: Plan A (75 thn): 150% UP Plan B (100 thn): 200% UP | I25: 100% ROP note: untuk Plan Heritage Infinite, apabila Tertanggung sudah Meninggal Dunia, Manfaat ini tetap akan dibayarkan ke Penerima Manfaat | K25: N/A | L25: Plan A: tidak ada Plan B: 100% ROP Plan C: 100% UP dasar | M25: 100% UP + Terminal Bonus (jika ada)
B26: Asuransi Tambahan (Riders) | C26: - Payor Benefit Plus - Waiver of Premium Plus | E26: N/A | F26: Sun Protection Plus | G26: MiTreasure Critical Cover | H26: MiPayor Benefit Plus: Meninggal Dunia & Ketidakmampuan Tetap Total | I26: N/A | K26: Pembebasan Premi jika terkena CI (77 Penyakit kritis) | L26: - Manulife Waiver of Premium (CI): 49 Penyakit Kritis di cover - Life Assurance Plus: perlindungan tambahan berupa Manfaat Meninggal Dunia | M26: N/A
B27: Manfaat Lainnya | C27: N/A | D27: N/A | E27: N/A | F27: Manfaat Pembebasan Premi (termasuk Premi Asuransi Tambahan jika ada) karena Pemilik Polis menderita Penyakit Kritis (77 CI dipertanggungkan) - Masa Tunggu 90 hari | G27: N/A | H27: N/A | I27: Manfaat Pembayaran Tunai Dijamin + Nilai Tambahan Manfaat Pembayaran Tunai (jika ada): - dibayarkan mulai Tahun Polis ke-5 berupa persentase ROP setiap bulan hingga 5% ROP | K27: N/A | L27: N/A | M27: Manfaat Pembebasan Premi jika terdiagnosis CI atau hingga Tertanggung mencapai Usia 75 tahun, mana yang terlebih dahulu terjadi
A28: Fitur Polis
B29: Penebusan Polis | C29: berupa persentase Nilai Tebus terbentuk | D29: N/A | E29: berupa Nilai Tebus terbentuk | F29: berupa Nilai Tebus terbentuk | G29: berupa Nilai Tunai terbentuk | H29: berupa Nilai Tunai terbentuk | I29: berupa Nilai Tunai terbentuk | K29: berupa persentase Nilai Tebus terbentuk | L29: Nilai Tunai terbentuk - Plan A: Premi Yang Belum Digunakan (Unused Premium) - Plan B & C: Nilai Tunai terbentuk (jika ada) | M29: Nilai Tunai terbentuk + Terminal Bonus (jika ada)
B30: Automatic Premium Loan (APL) | C30: N/A | E30: N/A | F30: N/A | H30: Tersedia | K30: N/A | L30: Plan A: tidak tersedia Plan B & C: tersedia | M30: Tersedia
B31: Pinjaman Polis | C31: N/A | D31: Tersedia | E31: N/A | F31: N/A | G31: N/A | H31: Tersedia | I31: N/A | K31: N/A | L31: Tersedia | M31: Tersedia
B32: Polis Bebas Premi Disertai Penurunan Uang Pertanggungan (Reduced Paid Up) | C32: N/A | D32: N/A | E32: N/A | F32: N/A | H32: Tersedia | K32: Tersedia | L32: Tersedia | M32: Tidak tersedia

Sheet Heritage+ vs PRUInfinity
A1: Illustration Comparison | G1: Benefit Comparison | L1: Feature Comparison
A2: Heritage+ | D2: PRUInfinity | G2: Manfaat Asuransi | I2: Heritage+ | J2: PRUInfinity | M2: Heritage+ | O2: PRUInfinity
A3: Ketentuan UW | B3: Full UW | D3: Ketentuan UW | E3: Full UW | G3: Manfaat Meninggal Dunia | I3: ✓ | J3: ✓ | L3: MPP | M3: Sekaligus, 2/5/10/15 tahun | O3: 3 atau 6 tahun
A4: MPP | B4: 5 tahun | D4: MPP | E4: 3 tahun | G4: Manfaat Tambahan MD karena Kecelakaan | I4: ✓ | J4: x | L4: Min. Premi | M4: Rp4,5 mio | O4: Rp150 mio
A5: Masa Pertanggungan | B5: hingga 99 tahun | D5: Masa Pertanggungan | E5: hingga 100 tahun | L5: Min. UP | M5: Rp500 mio | O5: Rp 3 bio
A6: Jenis Kelamin | B6: Pria | D6: Jenis Kelamin | E6: Pria | G6: Manfaat Terminal Illness | I6: ✓ | J6: x | L6: Ketentuan UW | M6: Full UW | O6: Full UW
A7: Usia Masuk | B7: 50 tahun | D7: Usia Masuk | E7: 50 tahun | G7: Manfaat Hidup | I7: ✓ (50% ROP) | J7: ✓ | L7: Mata Uang | M7: Rupiah dan USD | O7: Rupiah
A8: Plan | B8: Secure | D8: Plan | E8: N/A | G8: Manfaat Pemeriksaan Kesehatan | I8: ✓ | J8: x
A9: UP | B9: 3000000000 | D9: UP | E9: 3000000000 | G9: Manfaat Akhir Masa Pertanggungan | I9: ✓ | J9: ✓
G10: Penebusan Polis (Nilai Tunai) | I10: ✓ | J10: ✓ | L10: Ketentuan Manfaat Hidup PRUInfinity
A11: Perbandingan Premi
B12: Heritage+ | D12: PRUInfinity
A13: Premi per tahun | B13: ='Premi H+ 2 bio'!AL55*'Heritage+ vs PRUInfinity'!B9/1000 -> 349080000 | D13: 619971000
A14: Total Premi | B14: =B13*5 -> 1745400000 | D14: =D13*3 -> 1859913000
A16: Perbandingan Manfaat
A17: Tahun Polis | B17: Premi Tahunan | D17: Manfaat Meninggal Dunia karena Sebab Apapun | F17: Manfaat Tambahan Meninggal Dunia karena Kecelakaan | H17: Manfaat Hidup | J17: Manfaat Akhir Pertanggungan
B18: Heritage+ | C18: PRUInfinity | D18: Heritage+ | E18: PRUInfinity | F18: Heritage+ | G18: PRUInfinity | H18: Heritage+ | I18: PRUInfinity | J18: Heritage+ | K18: PRUInfinity
A19: 1 | B19: =$B$13 -> 349080000 | C19: =$D$13 -> 619971000 | D19: =$B$9 -> 3000000000 | E19: =$E$9 -> 3000000000 | G19: N/A
A20: 2 | B20: =$B$13 -> 349080000 | C20: =$D$13 -> 619971000 | D20: =$B$9 -> 3000000000 | E20: =$E$9 -> 3000000000 | M20: Feature & Benefit Strong Point: - Heritage+ memiliki pilihan MPP yang lebih panjang dan Usia masuk lebih awal dibandingkan PRUInfinity - Heritage+ memiliki pilihan mata uang USD. - Dari segi manfaat, Heritage+ lebih unggul dengan adanya Manfaat Tambahan Meninggal Dunia karena Kecelakaan, Manfaat Terminal Illness dan Pemeriksaan Kesehatan Weak Point: - Kenaikan booster UP pada PRUInfinity maksimal 250% UP, sedangkan Heritage+ 200% UP. Illustration Strong Point: - Berdasarkan comparison ilustrasi, dengan UP dan Usia Masuk yang sama, Premi Heritage+ lebih murah walaupun MPP lebih panjang. - Manfaat Hidup Heritage+ didapatkan lebih awal, dengan nominal yang lebih tinggi dibanding PRUInfinity. - Walaupun PRUInfinity memiliki fitur Booster UP, namun peningkatan UP pada Heritage+ secara nominal lebih besar (Tahun 5: BCAL 25%, PRU 15%), sehingga memberikan nilai proteksi yang lebih optimal. Weak Point: - Nilai Manfaat Akhir Masa Pertanggungan pada PRUInfinity 34% lebih tinggi dibandingkan Heritage+. NOTE: Berdasarkan perbandingan Minimum Premi dan UP, segmen market Heritage+ dan PRUInfinity berbeda. Heritage+ lebih cocok untuk segmen HNWI dan Affluent, sedangkan PRUInfinity lebih ditujukan bagi HNWI.
A21: 3 | B21: =$B$13 -> 349080000 | C21: =$D$13 -> 619971000 | D21: =$B$9 -> 3000000000 | E21: =$E$9 -> 3000000000
A22: 4 | B22: =$B$13 -> 349080000 | D22: =$B$9 -> 3000000000 | E22: =$E$9 -> 3000000000
A23: 5 | B23: =$B$13 -> 349080000 | D23: =$B$9 -> 3000000000 | E23: =$E$9 -> 3000000000
A24: 6 | D24: =125%*B9 -> 3750000000 | E24: 3450000000
A25: 7 | D25: =D24 -> 3750000000 | E25: 3600000000
A26: . | D26: . | E26: .
A27: 11 | D27: =150%*B9 -> 4500000000 | E27: 4200000000
A28: . | D28: . | E28: .
A29: 15 | D29: =D27 -> 4500000000 | E29: 4800000000 | H29: =50%*B14 -> 872700000
A30: 16 | D30: =160%*B9 -> 4800000000 | E30: 4330029000 | F30: =D30+B9 -> 7800000000 | I30: =100%*D13 -> 619971000
A31: 17 | D31: =D30 -> 4800000000 | E31: 4480029000
A32: 18 | D32: =D31 -> 4800000000 | E32: 4630029000
A33: . | D33: . | E33: .
A34: . | D34: . | E34: .
A35: 21 | D35: =170%*B9 -> 5100000000 | E35: 5080000000
A36: 22 | D36: =D35 -> 5100000000 | E36: 5230000000
A37: . | D37: . | E37: .
A38: . | D38: . | E38: .
A39: 32 | D39: =190%*B9 -> 5700000000 | E39: 6730029000
A40: 33 | D40: =D39 -> 5700000000 | E40: 6880029000
A41: . | D41: . | E41: .
...

Sheet Heritage+ vs Sun 100
A1: Illustration Comparison | G1: Benefit Comparison | L1: Feature Comparison
A2: Heritage+ | D2: Sun Proteksi Heritage 100 | G2: Manfaat Asuransi | I2: Heritage+ | J2: Sun Proteksi 100 | M2: Heritage+ | O2: Sun Proteksi 100
A3: Ketentuan UW | B3: Full UW | D3: Ketentuan UW | E3: Full UW | G3: Manfaat Meninggal Dunia | I3: ✓ | J3: ✓ | L3: MPP | M3: Sekaligus, 2/5/10/15 tahun | O3: 5 atau 10 tahun
A4: MPP | B4: 10 tahun | D4: MPP | E4: 10 tahun | G4: Manfaat Tambahan MD karena Kecelakaan | I4: ✓ | J4: x | L4: Min. Premi | M4: Rp4,5 mio | O4: Rp3,6 mio
A5: Masa Pertanggungan | B5: hingga 99 tahun | D5: Masa Pertanggungan | E5: hingga 100 tahun | L5: Min. UP | M5: Rp500 mio | O5: Rp 200 mio
A6: Jenis Kelamin | B6: Pria | D6: Jenis Kelamin | E6: Pria | G6: Manfaat Terminal Illness | I6: ✓ | J6: x | L6: Ketentuan UW | M6: Full UW | O6: Full UW
A7: Usia Masuk | B7: 40 tahun | D7: Usia Masuk | E7: 40 tahun | G7: Manfaat Hidup | I7: ✓ | J7: ✓ | L7: Mata Uang | M7: Rupiah dan USD | O7: Rupiah
A8: Plan | B8: Secure | D8: Plan | E8: Sun Golden 75 | G8: Manfaat Pemeriksaan Kesehatan | I8: ✓ | J8: X
A9: UP | B9: 1000000000 | D9: UP | E9: 1000000000 | G9: Manfaat Akhir Masa Pertanggungan | I9: ✓ | J9: ✓
G10: Manfaat Pembebasan Premi (CI) | I10: x | J10: ✓
A11: Perbandingan Premi | G11: Penebusan Polis (Nilai Tebus) | I11: ✓ | J11: ✓
B12: Heritage+ | D12: Sun Proteksi Heritage 100
A13: Premi per tahun | B13: ='Premi H+ 500 mio'!AR45*'Heritage+ vs Sun 100'!B9/1000 -> 48240000 | D13: 17633000 | G13: Ketentuan Manfaat Hidup | I13: ✓ | J13: ✓
A14: Total Premi | B14: =B13*10 -> 482400000 | D14: =D13*10 -> 176330000
A17: Perbandingan Manfaat
A18: Tahun Polis | B18: Premi Tahunan | D18: Manfaat Meninggal Dunia karena Sebab Apapun | F18: Manfaat Tambahan Meninggal Dunia karena Kecelakaan | H18: Manfaat Hidup | J18: Manfaat Akhir Pertanggungan
B19: Heritage+ | C19: Sun Proteksi 100 | D19: Heritage+ | E19: Sun Proteksi 100 | F19: Heritage+ | G19: Sun Proteksi 100 | H19: Heritage+ | I19: Sun Proteksi 100 | J19: Heritage+ | K19: Sun Proteksi 100
A20: 1 | B20: =$B$13 -> 48240000 | C20: =$D$13 -> 17633000 | D20: =$B$9 -> 1000000000 | E20: =$E$9 -> 1000000000 | G20: N/A
A21: 2 | B21: =$B$13 -> 48240000 | C21: =$D$13 -> 17633000 | D21: =$B$9 -> 1000000000 | E21: =$E$9 -> 1000000000 | M21: Feature & Benefit Strong Point: - Heritage+ memiliki variasi MPP yang lebih banyak. - Manfaat Meninggal Dunia pada produk Heritage+ lebih tinggi, yaitu hingga 200% UP sedangkan Sun Proteksi Heritage hanya 100% UP (tidak ada booster UP). - Heritage+ memiliki manfaat asuransi yang lebih lengkap, yaitu Manfaat Tambahan Meninggal Dunia karena Kecelakaan, Manfaat Terminal Illness, dan Manfaat Pemeriksaan Kesehatan. - Heritage+ tersedia dalam USD Weak Point: - Manfaat Pembebasan Premi pada Sun Proteksi 100 merupakan manfaat asuransi dasar, bukan riders seperti Heritage+ Illustration Strong Point: - Manfaat Hidup Heritage+ lebih cepat didapatkan, yaitu pada Usia Tertanggung 60 tahun, sedangkan Sun Proteksi 100 didapatkan pada Usia Tertanggung 75. - Nilai Manfaat Meninggal Dunia karena Sebab Apapun lebih besar dibandingkan Sun Proteksi 100. Weak Point: - Dengan ilustrasi yang sama, Premi Heritage+ lebih mahal dibandingkan Sun Proteksi Heritage 100 (2,7x). - Manfaat Pembebasan Premi pada Sun Proteksi Heritage 100 merupakan manfaat asuransi dasar, bukan bersifat tambahan seperti pada Heritage+. - Manfaat Akhir Pertanggungan pada produk Sun Proteksi Heritage 100 tidak dikurangi dengan Manfaat Hidup. (walaupun secara nominal, Heritage+ tetap lebih unggul)
A22: 3 | B22: =$B$13 -> 48240000 | C22: =$D$13 -> 17633000 | D22: =$B$9 -> 1000000000 | E22: =$E$9 -> 1000000000
A23: 4 | B23: =$B$13 -> 48240000 | C23: =$D$13 -> 17633000 | D23: =$B$9 -> 1000000000 | E23: =$E$9 -> 1000000000
A24: 5 | B24: =$B$13 -> 48240000 | C24: =$D$13 -> 17633000 | D24: =$B$9 -> 1000000000 | E24: =$E$9 -> 1000000000
A25: 6 | B25: =$B$13 -> 48240000 | C25: =$D$13 -> 17633000 | D25: =125%*B9 -> 1250000000 | E25: =$E$9 -> 1000000000
A26: 7 | B26: =$B$13 -> 48240000 | C26: =$D$13 -> 17633000 | D26: =D25 -> 1250000000 | E26: =$E$9 -> 1000000000
A27: 8 | B27: =$B$13 -> 48240000 | C27: =$D$13 -> 17633000 | D27: =D25 -> 1250000000 | E27: =$E$9 -> 1000000000
A28: 9 | B28: =$B$13 -> 48240000 | C28: =$D$13 -> 17633000 | D28: =D25 -> 1250000000 | E28: =$E$9 -> 1000000000
A29: 10 | B29: =$B$13 -> 48240000 | C29: =$D$13 -> 17633000 | D29: =D25 -> 1250000000 | E29: =$E$9 -> 1000000000
A30: 11 | D30: =D28 -> 1250000000 | E30: =$E$9 -> 1000000000
A31: . | D31: . | E31: =$E$9 -> 1000000000
A32: . | D32: . | E32: =$E$9 -> 1000000000
A33: 16 | D33: =150%*B9 -> 1500000000 | E33: =$E$9 -> 1000000000
A34: . | D34: . | E34: .
A35: . | D35: . | E35: .
A36: 21 | D36: =160%*B9 -> 1600000000 | E36: =E9 -> 1000000000 | F36: =D36+B9 -> 2600000000 | H36: =50%*B14 -> 241200000
A37: . | D37: . | E37: .
A38: . | D38: . | E38: .
A39: 26 | D39: =170%*B9 -> 1700000000 | E39: =E9 -> 1000000000
A40: . | D40: . | E40: .
A41: . | D41: . | E41: .
A42: 31 | D42: =180%*B9 -> 1800000000 | E42: =E9 -> 1000000000
...

Sheet Heritage+ vs X-tra Proteksi War
A1: Illustration Comparison | G1: Benefit Comparison | L1: Feature Comparison | S1: Strong Point: - Heritage+ memiliki variasi MPP yang lebih banyak. - Heritage+ memiliki manfaat asuransi yang lebih lengkap, yaitu Manfaat Tambahan Meninggal Dunia karena Kecelakaan, Manfaat Terminal Illness, dan Manfaat Pemeriksaan Kesehatan. - Pergerakan UP Manfaat MD pada Heritage+ lebih tinggi dibandingkan X-Tra Proteksi Waris, UP MD pada Heritage+ baru akan kalah pada Tahun Polis ke-40 (dengan asumsi menggunakan Terminal Bonus Tinggi) - Nominal Manfaat Hidup Heritage+ lebih tinggi dan lebih cepat didapatkan, pada case ini yaitu pada Usia Tertanggung 60 tahun (Tahun Polis ke-21). Sedangkan X-Tra Proteksi Waris baru didapatkan pada Usia Tertanggung 65 tahun. Weak Point: - Berdasarkan ilustrasi disamping, Premi Heritage+ lebih mahal dibandingkan X-Tra Proteksi Waris. - Manfaat Pembebasan Premi (CI) pada X-Tra Proteksi Waris merupakan manfaat basic, bukan rider seperti Heritage+. - Nominal Manfaat Akhir Pertanggungan pada X-Tra Proteksi Waris (dengan asumsi Terminal Bonus Tinggi dan Sedang) lebih besar dibandingkan Heritage+.
A2: Heritage+ | D2: X-Tra Proteksi Waris | G2: Manfaat Asuransi | I2: Heritage+ | J2: X-Tra Proteksi Waris | M2: Heritage+ | O2: X-Tra Proteksi Waris
A3: Ketentuan UW | B3: Full UW | D3: Ketentuan UW | E3: Full UW | G3: Manfaat Meninggal Dunia | I3: ✓ | J3: ✓ | L3: MPP | M3: Sekaligus, 2/5/10/15 tahun | O3: Sekaligus dan 5 tahun
A4: MPP | B4: Sekaligus | D4: MPP | E4: Sekaligus | G4: Manfaat Tambahan MD karena Kecelakaan | I4: ✓ | J4: x | L4: Min. Premi | M4: USD 505,75 | O4: USD 10.000
A5: Masa Pertanggungan | B5: hingga 99 tahun | D5: Masa Pertanggungan | E5: hingga 100 tahun | L5: Min. UP | M5: USD 35.000 | O5: Plan Prime, Excellence: USD 200.000 Plan Signature: USD 1.000.000
A6: Jenis Kelamin | B6: Pria | D6: Jenis Kelamin | E6: Pria | G6: Manfaat Terminal Illness | I6: ✓ | J6: x | L6: Ketentuan UW | M6: Full UW | O6: Full UW
A7: Usia Masuk | B7: 40 tahun | D7: Usia Masuk | E7: 40 tahun | G7: Manfaat Hidup | I7: ✓ | J7: ✓ | L7: Mata Uang | M7: Rupiah dan USD | O7: USD
A8: Plan | B8: Secure | D8: Plan | E8: Excellence | G8: Manfaat Pemeriksaan Kesehatan | I8: ✓ | J8: X
A9: UP | B9: USD 200.000 | D9: UP | E9: USD 200.000 | G9: Manfaat Akhir Masa Pertanggungan | I9: ✓ | J9: ✓
G10: Manfaat Pembebasan Premi (CI) | I10: x | J10: ✓
A11: Perbandingan Premi | G11: Penebusan Polis (Nilai Tebus) | I11: ✓ | J11: ✓
B12: Heritage+ | D12: X-Tra Proteksi Waris
A13: Premi sekaligus | B13: USD 109.576 | D13: USD 82.536
A14: Total Premi
A17: Perbandingan Manfaat
A18: Tahun Polis | B18: Premi Tahunan | D18: Kenaikan UP | F18: Manfaat Meninggal Dunia | J18: Manfaat Tambahan Meninggal Dunia karena Kecelakaan | L18: Manfaat Hidup | N18: Manfaat Akhir Pertanggungan
B19: Heritage+ | C19: X-Tra Proteksi Waris | D19: Heritage+ | E19: X-Tra Proteksi Waris | F19: Heritage+ | G19: X-Tra Proteksi Waris | J19: Heritage+ | K19: X-Tra Proteksi Waris | L19: Heritage+ | M19: X-Tra Proteksi Waris | N19: Heritage+ | O19: X-Tra Proteksi Waris
G20: Rendah | H20: Sedang | I20: Tinggi | O20: Rendah | P20: Sedang | Q20: Tinggi
A21: 1 | B21: =B13 -> USD 109.576 | C21: =D13 -> USD 82.536 | D21: USD 200.000 | E21: USD 200.000 | F21: USD 200.000 | G21: USD 200.000 | H21: USD 200.000 | I21: USD 200.000
A22: 2 | D22: USD 200.000 | E22: USD 200.000 | F22: USD 200.000 | G22: USD 200.000 | H22: USD 200.613 | I22: USD 200.720
A23: 3 | D23: USD 200.000 | E23: USD 202.000 | F23: USD 200.000 | G23: USD 202.000 | H23: USD 202.863 | I23: USD 203.030
A24: 4 | D24: USD 200.000 | E24: USD 202.000 | F24: USD 200.000 | G24: USD 202.000 | H24: USD 203.020 | I24: USD 203.383
A25: 5 | D25: USD 200.000 | E25: USD 204.000 | F25: USD 200.000 | G25: USD 204.000 | H25: USD 205.259 | I25: USD 205.781
A26: 6 | D26: USD 250.000 | E26: USD 204.000 | F26: USD 250.000 | G26: USD 204.000 | H26: USD 205.523 | I26: USD 206.231
A27: 7 | D27: USD 250.000 | E27: USD 206.000 | F27: USD 250.000 | G27: USD 206.000 | H27: USD 207.815 | I27: USD 208.739
A28: 8 | D28: USD 250.000 | E28: USD 206.000 | F28: USD 250.000 | G28: USD 206.000 | H28: USD 208.137 | I28: USD 209.309
A29: 9 | D29: USD 250.000 | E29: USD 208.000 | F29: USD 250.000 | G29: USD 208.000 | H29: USD 210.493 | I29: USD 211.951
A30: 10 | D30: USD 250.000 | E30: USD 208.000 | F30: USD 250.000 | G30: USD 208.000 | H30: USD 210.884 | I30: USD 212.671
A31: 11 | D31: USD 300.000 | E31: USD 210.000 | F31: USD 300.000 | G31: USD 210.000 | H31: USD 213.313 | I31: USD 215.478
A32: .
A33: .
A34: 20 | D34: USD 350.000 | E34: USD 218.000 | F34: USD 350.000 | G34: USD 218.000 | H34: USD 227.601 | I34: USD 236.704 | J34: USD 550.000 | K34: N/A
A35: 21 | D35: USD 370.000 | E35: No Info | F35: USD 370.000 | G35: No Info | L35: USD 100.000
A36: .
A37: 25 | D37: USD 370.000 | E37: USD 224.000 | F37: USD 370.000 | G37: USD 224.000 | H37: USD 238.669 | I37: USD 256.005 | M37: USD 40.000
A38: .
A39: 30 | D39: USD 390.000 | E39: USD 228.000 | F39: USD 390.000 | G39: USD 228.000 | H39: USD 259.219 | I39: USD 322.945
A40: .
A41: 35 | D41: USD 400.000 | E41: USD 234.000 | F41: USD 400.000 | G41: USD 234.000 | H41: USD 281.309 | I41: USD397.559
A43: 40 | D43: USD 400.000 | E43: USD 238.000 | F43: USD 400.000 | G43: USD 238.000 | H43: USD 308.225 | I43: USD 518.446
...

Sheet Heritage+ vs Manu Prime
A1: Illustration Comparison | G1: Benefit Comparison | M1: Feature Comparison
A2: Heritage+ | D2: Manulife Prime | G2: Manfaat Asuransi | I2: Heritage+ | J2: Manulife Prime | N2: Heritage+ | P2: Manulife Prime
A3: Ketentuan UW | B3: Full UW (Non Medis) | D3: Ketentuan UW | E3: SIO | G3: Manfaat Meninggal Dunia | I3: ✓ | J3: ✓ | M3: MPP | N3: Sekaligus, 2/5/10/15 tahun | P3: Sekaligus, 3/5 tahun
A4: MPP | B4: 5 tahun | D4: MPP | E4: 5 tahun | G4: Manfaat Tambahan MD karena Kecelakaan | I4: ✓ | J4: x | M4: Min. Premi | N4: Rp4,5 mio | P4: Rp11,4 mio
A5: Masa Pertanggungan | B5: hingga 99 tahun | D5: Masa Pertanggungan | E5: hingga 100 tahun | M5: Min. UP | N5: Rp500 mio | P5: No Info
A6: Jenis Kelamin | B6: Pria | D6: Jenis Kelamin | E6: Pria | G6: Manfaat Terminal Illness | I6: ✓ | J6: x | M6: Ketentuan UW | N6: Full UW | P6: SIO & Full UW
A7: Usia Masuk | B7: 40 tahun | D7: Usia Masuk | E7: 40 tahun | G7: Manfaat Pemeriksaan Kesehatan | I7: ✓ | J7: X | M7: Mata Uang | N7: Rupiah dan USD | P7: Rupiah dan USD
A8: Plan | B8: Essential | D8: Plan | E8: Plan B - 100 tahun | G8: Manfaat Akhir Masa Pertanggungan | I8: ✓ | J8: ✓
A9: UP | B9: 1000000000 | D9: UP | E9: 1000000000 | G9: Penebusan Polis (Nilai Tunai) | I9: ✓ | J9: ✓ | M9: Ketentuan UW | N9: SIO | P9: Full UW
N10: untuk Usia ≤ 60 tahun dengan UP ≤ 5 bio / USD500.000 | P10: - seluruh Usia dengan UP > Rp 5 bio / USD500.000 - Usia Tertanggung > 60 tahun dgn UP ≤ Rp 5 bio / USD500.000 - Jika PP memilih Pertanggungan Tambahan
A11: Perbandingan Premi
B12: Heritage+ | D12: Manulife Prime
A13: Premi per tahun | B13: ='Premi H+ 500 mio'!N45*'Heritage+ vs Manu Prime'!B9/1000 -> 76820000 | D13: 159810000
A14: Total Premi | B14: =B13*5 -> 384100000 | D14: =D13*5 -> 799050000
A16: Perbandingan Manfaat
A17: Tahun Polis | B17: Premi Tahunan | D17: Manfaat Meninggal Dunia karena Sebab Apapun | F17: Manfaat Tambahan Meninggal Dunia karena Kecelakaan | H17: Manfaat Akhir Pertanggungan
B18: Heritage+ | C18: Manulife Prime | D18: Heritage+ | E18: Manulife Prime | F18: Heritage+ | G18: Manulife Prime | H18: Heritage+ | I18: Manulife Prime
A19: 1 | B19: =$B$13 -> 76820000 | C19: =$D$13 -> 159810000 | D19: =$B$9 -> 1000000000 | E19: =$E$9 -> 1000000000 | G19: N/A
A20: 2 | B20: =$B$13 -> 76820000 | C20: =$D$13 -> 159810000 | D20: =$B$9 -> 1000000000 | E20: =$E$9 -> 1000000000 | K20: Feature, Benefit, & Illustration Strong Point: - Dari segi Manfaat, Heritage+ lebih unggul dibandingkan Prime karena memiliki Manfaat Tambahan Meninggal Dunia karena Kecelakaan, Manfaat Terminal Illness, dan Manfaat Pemeriksaan Kesehatan. - Dari segi Premi dengan ilustrasi yang sama, Premi Heritage+ lebih murah dibandingkan Prime. - Walaupun batas kenaikan UP sama-sama hingga 200%, namun kenaikan UP pada Heritage+ lebih cepat dibandingkan Prime. Weak Point: - Terdapat opsi ketentuan UW SIO pada produk Manulife Prime. Untuk ilustrasi yang sama, ketentuan UW pada Prime adalah SIO sedangkan Heritage+ Full UW. Conclusion: Secara keseluruhan, produk Heritage+ lebih unggul dengan Premi yang lebih murah, Manfaat Asuransi yang lebih lengkap, dan kenaikan UP yang lebih cepat dibandingkan produk Prime.
A21: 3 | B21: =$B$13 -> 76820000 | C21: =$D$13 -> 159810000 | D21: =$B$9 -> 1000000000 | E21: =$E$9 -> 1000000000
A22: 4 | B22: =$B$13 -> 76820000 | C22: =$D$13 -> 159810000 | D22: =$B$9 -> 1000000000 | E22: =$E$9 -> 1000000000
A23: 5 | B23: =$B$13 -> 76820000 | C23: =$D$13 -> 159810000 | D23: =$B$9 -> 1000000000 | E23: =$E$9 -> 1000000000
A24: 6 | D24: =125%*B9 -> 1250000000 | E24: =$E$9 -> 1000000000
A25: 7 | D25: =D24 -> 1250000000 | E25: =$E$9 -> 1000000000
A26: 8 | D26: =D24 -> 1250000000 | E26: =$E$9 -> 1000000000
A27: 9 | D27: =D24 -> 1250000000 | E27: =E9 -> 1000000000
A28: 10 | D28: =D24 -> 1250000000 | E28: =E9*150% -> 1500000000
A29: 11 | D29: =D27 -> 1250000000 | E29: =E28 -> 1500000000
A30: . | D30: .
A31: . | D31: .
A32: 16 | D32: =150%*B9 -> 1500000000 | E32: =E29 -> 1500000000 | F32: =D32+B9 -> 2500000000
A33: . | D33: . | E33: .
A34: . | D34: . | E34: .
A35: 21 | D35: =175%*B9 -> 1750000000 | E35: =E32 -> 1500000000
A36: . | D36: . | E36: .
A37: . | D37: . | E37: .
A38: 26 | D38: =200%*B9 -> 2000000000 | E38: =200%*E9 -> 2000000000
A39: . | D39: . | E39: .
A40: . | D40: . | E40: .
A41: 59 | D41: =D38 -> 2000000000 | H41: =D41 -> 2000000000
...

Sheet Heritage+ vs MDLA
A1: Illustration Comparison | G1: Benefit Comparison | M1: Feature Comparison
A2: Heritage+ | D2: MDLA | G2: Manfaat Asuransi | I2: Heritage+ | J2: MDLA | N2: Heritage+ | P2: MDLA
A3: Ketentuan UW | B3: Full UW | D3: Ketentuan UW | E3: Full UW | G3: Manfaat Meninggal Dunia | I3: ✓ | J3: ✓ | M3: MPP | N3: Sekaligus, 2/5/10/15 tahun | P3: 5/10/15/20 tahun
A4: MPP | B4: 20 tahun | D4: MPP | E4: 20 tahun | G4: Manfaat Tambahan MD karena Kecelakaan | I4: ✓ | J4: x | M4: Min. Premi per tahun | N4: Rp4,5 mio | P4: Rp5 mio
A5: Masa Pertanggungan | B5: hingga 99 tahun | D5: Masa Pertanggungan | E5: 40 tahun | M5: Min. UP | N5: Rp500 mio | P5: Rp100 mio
A6: Jenis Kelamin | B6: Pria | D6: Jenis Kelamin | E6: Pria | G6: Manfaat Terminal Illness | I6: ✓ | J6: x | M6: Ketentuan UW | N6: Full UW | P6: Full UW
A7: Usia Masuk | B7: 30 tahun | D7: Usia Masuk | E7: 30 tahun | G7: Manfaat Pemeriksaan Kesehatan | I7: ✓ | J7: X | M7: Mata Uang | N7: Rupiah dan USD | P7: Rupiah
A8: Plan | B8: Essential | D8: Plan | E8: Plan C | G8: Manfaat Akhir Masa Pertanggungan | I8: ✓ | J8: ✓ (hanya Plan B dan C)
A9: UP | B9: 1000000000 | D9: UP | E9: 1000000000 | G9: Penebusan Polis | I9: ✓ | J9: ✓ (Nilai Tunai )
A11: Perbandingan Premi
B12: Heritage+ | D12: MDLA
A13: Premi per tahun | B13: =21.04*1000000 -> 21040000 | D13: 13360800
A14: Total Premi | B14: =B13*15 -> 315600000 | D14: =D13*20 -> 267216000
A16: Perbandingan Manfaat
A17: Tahun Polis | B17: Premi Tahunan | D17: Manfaat Meninggal Dunia karena Sebab Apapun | F17: Manfaat Tambahan Meninggal Dunia karena Kecelakaan | H17: Manfaat Akhir Pertanggungan
B18: Heritage+ | C18: MDLA | D18: Heritage+ | E18: MDLA | F18: Heritage+ | G18: MDLA | H18: Heritage+ | I18: MDLA
A19: 1 | B19: =$B$13 -> 21040000 | C19: =$D$13 -> 13360800 | D19: =$B$9 -> 1000000000 | E19: =$E$9 -> 1000000000 | G19: N/A
A20: 2 | B20: =$B$13 -> 21040000 | C20: =$D$13 -> 13360800 | D20: =$B$9 -> 1000000000 | E20: =$E$9 -> 1000000000 | K20: Feature, Benefit, & Illustration Strong Point: - Dari segi Manfaat, Heritage+ lebih unggul dibandingkan MDLA karena memiliki Manfaat Tambahan Meninggal Dunia karena Kecelakaan, Manfaat Terminal Illness, Manfaat Pemeriksaan Kesehatan. - Dari segi Premi dengan ilustrasi yang sama, Premi Heritage+ lebih mahal 18% namun UP Heritage+ bisa meningkat hingga 200% UP sedangkan UP pada MDLA stagnan. - Heritage+ memiliki mata uang untuk USD, sedangkan MDLA hanya Rupiah saja. Weak Point: - Premi Heritage+ lebih mahal 18% dibandingkan dengan MDLA.
A21: 3 | B21: =$B$13 -> 21040000 | C21: =$D$13 -> 13360800 | D21: =$B$9 -> 1000000000 | E21: =$E$9 -> 1000000000
A22: 4 | B22: =$B$13 -> 21040000 | C22: =$D$13 -> 13360800 | D22: =$B$9 -> 1000000000 | E22: =$E$9 -> 1000000000
A23: 5 | B23: =$B$13 -> 21040000 | C23: =$D$13 -> 13360800 | D23: =$B$9 -> 1000000000 | E23: =$E$9 -> 1000000000
A24: 6 | B24: =$B$13 -> 21040000 | C24: =$D$13 -> 13360800 | D24: =125%*B9 -> 1250000000 | E24: =$E$9 -> 1000000000
A25: 7 | B25: =$B$13 -> 21040000 | C25: =$D$13 -> 13360800 | D25: =D24 -> 1250000000 | E25: =$E$9 -> 1000000000
A26: 8 | B26: =$B$13 -> 21040000 | C26: =$D$13 -> 13360800 | D26: =D24 -> 1250000000 | E26: =$E$9 -> 1000000000
A27: 9 | B27: =$B$13 -> 21040000 | C27: =$D$13 -> 13360800 | D27: =D24 -> 1250000000 | E27: =E9 -> 1000000000
A28: 10 | B28: =$B$13 -> 21040000 | C28: =$D$13 -> 13360800 | D28: =D24 -> 1250000000 | E28: =E25 -> 1000000000
A29: 11 | B29: =$B$13 -> 21040000 | C29: =$D$13 -> 13360800 | D29: =B9*150% -> 1500000000 | E29: =E25 -> 1000000000
A30: . | B30: =$B$13 -> 21040000 | C30: =$D$13 -> 13360800 | D30: .
A31: 15 | B31: =$B$13 -> 21040000 | C31: =$D$13 -> 13360800 | D31: =D29 -> 1500000000 | E31: =E29 -> 1000000000
A32: 16 | C32: =$D$13 -> 13360800 | D32: =150%*B9 -> 1500000000 | E32: =E29 -> 1000000000 | F32: =D32+B9 -> 2500000000
A33: . | C33: =$D$13 -> 13360800 | D33: . | E33: .
A34: . | C34: =$D$13 -> 13360800 | D34: . | E34: .
A35: 21 | D35: =175%*B9 -> 1750000000 | E35: =E32 -> 1000000000
A36: . | D36: . | E36: .
A37: . | D37: . | E37: .
A38: 26 | D38: =200%*B9 -> 2000000000 | E38: =E35 -> 1000000000
A39: . | D39: . | E39: .
A40: . | D40: . | E40: .
A41: 40 | D41: =D38 -> 2000000000 | E41: =E38 -> 1000000000 | I41: =E9 -> 1000000000
A42: .
...

Sheet Heritage+ vs AIA WPP (Non LB)
A1: Illustration Comparison | G1: Benefit Comparison | L1: Feature Comparison
A2: Heritage+ | D2: AIA WPP | G2: Manfaat Asuransi | I2: Heritage+ | J2: AIA WPP | M2: Heritage+ | O2: AIA WPP
A3: Ketentuan UW | B3: Full UW | D3: Ketentuan UW | E3: Full UW | G3: Manfaat Meninggal Dunia | I3: ✓ | J3: ✓ | L3: MPP | M3: Sekaligus, 2/5/10/15 tahun | O3: Sekaligus, 2, 5 tahun
A4: MPP | B4: 5 tahun | D4: MPP | E4: 5 tahun | G4: Manfaat Tambahan MD karena Kecelakaan | I4: ✓ | J4: x | L4: Min. Premi | M4: Rp4,5 mio | O4: Rp100 mio
A5: Masa Pertanggungan | B5: hingga 99 tahun | D5: Masa Pertanggungan | L5: Min. UP | M5: Rp500 mio | O5: Rp 2 bio
A6: Jenis Kelamin | B6: Pria | D6: Jenis Kelamin | E6: Pria | G6: Manfaat Tambahan MD karena Kecelakaan di Transportasi Umum | I6: x | J6: ✓ | L6: Ketentuan UW | M6: Full UW | O6: Full UW
A7: Usia Masuk | B7: 35 tahun | D7: Usia Masuk | E7: 35 tahun | G7: Manfaat Terminal Illness | I7: ✓ | J7: x | L7: Mata Uang | M7: Rupiah dan USD | O7: Rupiah
A8: Plan | B8: Essential | D8: Plan | E8: Elevate | G8: Manfaat Pemeriksaan Kesehatan | I8: ✓ | J8: x
A9: UP | B9: 2000000000 | D9: UP | E9: 2000000000 | G9: Manfaat Akhir Masa Pertanggungan | I9: ✓ | J9: ✓
G10: Penebusan Polis (Nilai Tunai) | I10: ✓ | J10: x
A11: Perbandingan Premi
B12: Heritage+ | D12: AIA WPP
A13: Premi per tahun | B13: ='Premi H+ 2 bio'!N40*'Heritage+ vs AIA WPP (Non LB)'!B9/1000 -> 114820000 | D13: 131000000
A14: Total Premi | B14: =B13*5 -> 574100000 | D14: =D13*5 -> 655000000
A16: Perbandingan Manfaat
A17: Tahun Polis | B17: Premi Tahunan | D17: Manfaat Meninggal Dunia karena Sebab Apapun | F17: Manfaat Tambahan Meninggal Dunia karena Kecelakaan | H17: Manfaat Akhir Pertanggungan
B18: Heritage+ | C18: AIA WPP | D18: Heritage+ | E18: AIA WPP | F18: Heritage+ | G18: AIA WPP | H18: Heritage+ | I18: AIA WPP
A19: 1 | B19: =$B$13 -> 114820000 | C19: =$D$13 -> 131000000 | D19: =$B$9 -> 2000000000 | E19: =$E$9 -> 2000000000
A20: 2 | B20: =$B$13 -> 114820000 | C20: =$D$13 -> 131000000 | D20: =$B$9 -> 2000000000 | E20: =$E$9 -> 2000000000 | K20: Feature & Benefit Strong Point: - Heritage+ memiliki pilihan mata uang USD. - Dari segi manfaat, Heritage+ lebih unggul dengan adanya Manfaat Tambahan Meninggal Dunia karena Kecelakaan, Manfaat Terminal Illness, dan Penebusan Polis Weak Point: - Kenaikan booster UP pada AIA WPP maksimal 300% UP, sedangkan Heritage+ 200% UP. - AIA WPP memiliki manfaat tambahan MD karena Kecelakaan di transportasi umum sebesar 150% UP Illustration Strong Point: - Berdasarkan comparison ilustrasi, dengan UP dan Usia Masuk yang sama, Premi Heritage+ lebih murah dibandingkan AIA WPP. - Walaupun booster UP AIA WPP hingga 300% UP, namun jika dilihat UP AIA WPP baru menyaingi Heritage+ di Tahun Polis ke-37, yaitu ketika Usia Nasabah 72 tahun Weak Point: - Nilai Manfaat Akhir Masa Pertanggungan pada AIA WPP lebih tinggi dibandingkan Heritage+. NOTE: Berdasarkan perbandingan Minimum Premi dan UP, segmen market Heritage+ dan AIA WPP berbeda. Heritage+ lebih cocok untuk segmen HNWI dan Affluent, sedangkan AIA WPP lebih ditujukan bagi HNWI.
A21: 3 | B21: =$B$13 -> 114820000 | C21: =$D$13 -> 131000000 | D21: =$B$9 -> 2000000000 | E21: =$E$9 -> 2000000000
A22: 4 | B22: =$B$13 -> 114820000 | C22: =D13 -> 131000000 | D22: =$B$9 -> 2000000000 | E22: =$E$9*1.1 -> 2200000000
A23: 5 | B23: =$B$13 -> 114820000 | C23: =D13 -> 131000000 | D23: =$B$9 -> 2000000000 | E23: =$E$9*1.1 -> 2200000000
A24: 6 | D24: =125%*B9 -> 2500000000 | E24: =$E$9*1.1 -> 2200000000
A25: 7 | D25: =D24 -> 2500000000 | E25: =$E$9*1.2 -> 2400000000
A26: 8 | D26: =D25 -> 2500000000 | E26: =$E$9*1.2 -> 2400000000
A27: 9 | D27: =D26 -> 2500000000 | E27: =$E$9*1.2 -> 2400000000
A28: 10 | D28: =D27 -> 2500000000 | E28: =E9*1.3 -> 2600000000
A29: 11 | D29: =150%*$B$9 -> 3000000000 | E29: =$E$9*1.3 -> 2600000000
A30: . | D30: =150%*$B$9 -> 3000000000 | E30: =$E$9*1.3 -> 2600000000
A31: 13 | D31: =150%*$B$9 -> 3000000000 | E31: =$E$9*1.4 -> 2800000000 | F31: =D31+B9 -> 5000000000 | G31: =E31+E9 -> 4800000000
A32: . | D32: =150%*$B$9 -> 3000000000 | E32: =$E$9*1.4 -> 2800000000
A33: . | D33: =150%*$B$9 -> 3000000000 | E33: =$E$9*1.4 -> 2800000000
A34: 16 | D34: =175%*$B$9 -> 3500000000 | E34: =$E$9*1.5 -> 3000000000
A35: 17 | D35: =175%*$B$9 -> 3500000000 | E35: =$E$9*1.5 -> 3000000000
A36: 18 | D36: =175%*$B$9 -> 3500000000 | E36: =$E$9*1.5 -> 3000000000
A37: 19 | D37: =175%*$B$9 -> 3500000000 | E37: =$E$9*1.6 -> 3200000000
A38: 20 | D38: =175%*$B$9 -> 3500000000 | E38: =$E$9*1.6 -> 3200000000
A39: 21 | D39: =200%*$B$9 -> 4000000000 | E39: =$E$9*1.6 -> 3200000000
A40: 22 | D40: =200%*$B$9 -> 4000000000 | E40: =$E$9*1.7 -> 3400000000
A41: 23 | D41: =200%*$B$9 -> 4000000000 | E41: =$E$9*1.7 -> 3400000000
...

Sheet Heritage+ vs AIA WPP (LB)
A1: Illustration Comparison | I1: Benefit Comparison | N1: Feature Comparison
A2: Heritage+ | D2: AIA WPP | I2: Manfaat Asuransi | K2: Heritage+ | L2: AIA WPP | O2: Heritage+ | Q2: AIA WPP
A3: Ketentuan UW | B3: Full UW | D3: Ketentuan UW | E3: Full UW | I3: Manfaat Meninggal Dunia | K3: ✓ | L3: ✓ | N3: MPP | O3: Sekaligus, 2/5/10/15 tahun | Q3: Sekaligus, 2, 5 tahun
A4: MPP | B4: 5 tahun | D4: MPP | E4: 5 tahun | I4: Manfaat Tambahan MD karena Kecelakaan | K4: ✓ | L4: x | N4: Min. Premi | O4: Rp4,5 mio | Q4: Rp100 mio
A5: Masa Pertanggungan | B5: hingga 99 tahun | D5: Masa Pertanggungan | N5: Min. UP | O5: Rp500 mio | Q5: Rp 2 bio
A6: Jenis Kelamin | B6: Pria | D6: Jenis Kelamin | E6: Pria | I6: Manfaat Tambahan MD karena Kecelakaan di Transportasi Umum | K6: x | L6: ✓ | N6: Ketentuan UW | O6: Full UW | Q6: Full UW
A7: Usia Masuk | B7: 40 tahun | D7: Usia Masuk | E7: 40 tahun | I7: Manfaat Hidup | K7: ✓ (50% ROP) | L7: ✓ (25% UP Awal) | N7: Mata Uang | O7: Rupiah dan USD | Q7: Rupiah
A8: Plan | B8: Secure | D8: Plan | E8: Viva | I8: Manfaat Terminal Illness | K8: ✓ | L8: x
A9: UP | B9: 2000000000 | D9: UP | E9: 2000000000 | I9: Manfaat Pemeriksaan Kesehatan | K9: ✓ | L9: ✓
I10: Manfaat Akhir Masa Pertanggungan | K10: ✓ | L10: ✓
A11: Perbandingan Premi | I11: Penebusan Polis (Nilai Tunai) | K11: ✓ | L11: x
B12: Heritage+ | D12: AIA WPP
A13: Premi per tahun | B13: ='Premi H+ 2 bio'!AL45*'Heritage+ vs AIA WPP (LB)'!B9/1000 -> 163660000 | D13: 172000000
A14: Total Premi | B14: =B13*5 -> 818300000 | D14: =D13*5 -> 860000000
A16: Perbandingan Manfaat
A17: Tahun Polis | B17: Premi Tahunan | D17: Manfaat Meninggal Dunia karena Sebab Apapun | F17: Manfaat Hidup | H17: Manfaat Tambahan Meninggal Dunia karena Kecelakaan | J17: Manfaat Akhir Pertanggungan
B18: Heritage+ | C18: AIA WPP | D18: Heritage+ | E18: AIA WPP | F18: Heritage+ | G18: AIA WPP | H18: Heritage+ | I18: AIA WPP | J18: Heritage+ | K18: AIA WPP
A19: 1 | B19: =$B$13 -> 163660000 | C19: =$D$13 -> 172000000 | D19: =$B$9 -> 2000000000 | E19: =$E$9 -> 2000000000
A20: 2 | B20: =$B$13 -> 163660000 | C20: =$D$13 -> 172000000 | D20: =$B$9 -> 2000000000 | E20: =$E$9 -> 2000000000 | M20: Feature & Benefit Strong Point: - Heritage+ memiliki pilihan mata uang USD. - Dari segi manfaat, Heritage+ lebih unggul dengan adanya Manfaat Tambahan Meninggal Dunia karena Kecelakaan, Manfaat Terminal Illness, dan Penebusan Polis Weak Point: - Kenaikan booster UP pada AIA WPP maksimal 300% UP, sedangkan Heritage+ 200% UP. - AIA WPP memiliki manfaat tambahan MD karena Kecelakaan di transportasi umum sebesar 150% UP Illustration Strong Point: - Berdasarkan comparison ilustrasi, dengan UP dan Usia Masuk yang sama, Premi Heritage+ lebih murah dibandingkan AIA WPP. - Walaupun booster UP AIA WPP hingga 300% UP, namun jika dilihat UP AIA WPP baru menyaingi Heritage+ di Tahun Polis terakhir. Weak Point: - Nilai Manfaat Akhir Masa Pertanggungan pada AIA WPP lebih tinggi dibandingkan Heritage+. - Nominal Manfaat Hidup AIA WPP lebih besar dibandingkan Heritage+ NOTE: Berdasarkan perbandingan Minimum Premi dan UP, segmen market Heritage+ dan AIA WPP berbeda. Heritage+ lebih cocok untuk segmen HNWI dan Affluent, sedangkan AIA WPP lebih ditujukan bagi HNWI.
A21: 3 | B21: =$B$13 -> 163660000 | C21: =$D$13 -> 172000000 | D21: =$B$9 -> 2000000000 | E21: =$E$9 -> 2000000000
A22: 4 | B22: =$B$13 -> 163660000 | C22: =D13 -> 172000000 | D22: =$B$9 -> 2000000000 | E22: =$E$9*1.1 -> 2200000000
A23: 5 | B23: =$B$13 -> 163660000 | C23: =D13 -> 172000000 | D23: =$B$9 -> 2000000000 | E23: =$E$9*1.1 -> 2200000000
A24: 6 | D24: =125%*B9 -> 2500000000 | E24: =$E$9*1.1 -> 2200000000
A25: 7 | D25: =D24 -> 2500000000 | E25: =$E$9*1.2 -> 2400000000
A26: 8 | D26: =D25 -> 2500000000 | E26: =$E$9*1.2 -> 2400000000
A27: 9 | D27: =D26 -> 2500000000 | E27: =$E$9*1.2 -> 2400000000
A28: 10 | D28: =D27 -> 2500000000 | E28: =E9*1.3 -> 2600000000
A29: 11 | D29: =150%*$B$9 -> 3000000000 | E29: =$E$9*1.3 -> 2600000000
A30: . | D30: =150%*$B$9 -> 3000000000 | E30: =$E$9*1.3 -> 2600000000
A31: 13 | D31: =150%*$B$9 -> 3000000000 | E31: =$E$9*1.4 -> 2800000000 | H31: =D31+B9 -> 5000000000 | I31: =E31+E9 -> 4800000000
A32: . | D32: =150%*$B$9 -> 3000000000 | E32: =$E$9*1.4 -> 2800000000
A33: . | D33: =150%*$B$9 -> 3000000000 | E33: =$E$9*1.4 -> 2800000000
A34: 16 | D34: =175%*$B$9 -> 3500000000 | E34: =$E$9*1.5 -> 3000000000
A35: 17 | D35: =175%*$B$9 -> 3500000000 | E35: =$E$9*1.5 -> 3000000000
A36: 18 | D36: =175%*$B$9 -> 3500000000 | E36: =$E$9*1.5 -> 3000000000
A37: 19 | D37: =175%*$B$9 -> 3500000000 | E37: =$E$9*1.6 -> 3200000000
A38: 20 | D38: =175%*$B$9 -> 3500000000 | E38: =$E$9*1.6 -> 3200000000 | F38: =50%*B14 -> 409150000
A39: 21 | D39: =(185%*$B$9)-$F$38 -> 3290850000 | E39: =$E$9*1.6 -> 3200000000 | G39: 500000000
A40: 22 | D40: =(185%*$B$9)-$F$38 -> 3290850000 | E40: =($E$9*1.7)-$G$39 -> 2900000000
A41: 23 | D41: =(185%*$B$9)-$F$38 -> 3290850000 | E41: =($E$9*1.7)-$G$39 -> 2900000000
...

Sheet Heritage+ vs AlliSya Legacy
A1: Product Information | F1: Premium Comparison
B2: BCA Life - Heritage+ | C2: Allianz - AlliSya Legacy Max | H2: Heritage+ | J2: AlliSya Legacy Max
A3: Jenis Produk | B3: Seumur Hidup Kombinasi | C3: Dwiguna Tradisional Syariah | F3: Plan | H3: Secure | J3: N/A
A4: Ketentuan UW | B4: Full UW | C4: Full UW | F4: Jenis Kelamin | H4: Pria | J4: Pria
A5: MPP | B5: Sekaligus, 2, 5,10, atau 15 tahun | C5: Sekaligus, 5,10, atau 15 tahun | F5: Usia Masuk | H5: 35 tahun | J5: 35 tahun
A6: Masa Pertanggungan | B6: hingga 99 tahun | C6: hingga 120 tahun | F6: MPP | H6: 10 tahun | J6: 15 tahun
A7: Uang Pertanggungan | B7: Min. Rp500 juta | C7: Min.Rp200 juta | F7: UP | H7: 500000000 | J7: 500000000
A8: Premi | B8: Min. Rp4.515.000 | C8: No Info | F8: Premi per Tahun | H8: ='Premi H+ 500 mio'!AR40*500000 -> 18875000 | J8: =1084000*12 -> 13008000
A9: Usia Masuk | B9: 6 bulan - 70 tahun | F9: Total Premi | H9: =H8*10 -> 188750000 | J9: =J8*15 -> 195120000
F10: Illustration Comparison
F11: Tahun Polis | G11: Manfaat Meninggal Dunia | J11: Manfaat Hidup | M11: Manfaat Akhir Masa Pertanggungan
G12: Heritage+ | H12: AlliSya Legacy Max | J12: Heritage+ | L12: AlliSya Legacy Max | M12: Heritage+ | O12: AlliSya Legacy Max
A13: Mata Uang | B13: Rupiah & USD | C13: Rupiah | F13: 1 | G13: =H7 -> 500000000 | H13: =J7 -> 500000000
A14: Benefit Comparison | F14: . | G14: . | H14: .
F15: 6 | G15: =H7*1.25 -> 625000000 | H15: =J7 -> 500000000
A16: Plan | B16: Secure: dengan Manfaat Hidup | C16: N/A | F16: . | G16: . | H16: .
B17: Essential: tanpa Manfaat Hidup | F17: 11 | G17: =H7*1.5 -> 750000000 | H17: =H15 -> 500000000
A18: Manfaat Meninggal Dunia karena Sebab Apapun | B18: UP hingga 200% UP (kenaikan UP 25% per 5 tahun) dikurangi Manfaat Hidup dan Manfaat TI yang sudah dibayarkan (jika ada) | C18: 100% Santunan Asuransi + Booster SA Booster SA adalah penambahan sebesar 10% dari SA setiap 10 Tahun Polis berdasarkan: Note: - batas maksimum booster SA adalah 50% dari SA awal untuk Asuransi Dasar | F18: . | G18: . | H18: .
F19: 16 | G19: =H7*1.75 -> 875000000 | H19: =J7 -> 500000000
F20: . | G20: . | H20: .
F21: 21 | G21: =H7*2 -> 1000000000 | H21: =J7 -> 500000000
F22: . | G22: . | H22: .
F23: 25 | G23: =G21 -> 1000000000 | H23: =J7*1.1 -> 550000000 | J23: =50%*H9 -> 94375000 | L23: =70%*J9 -> 136584000
A24: Manfaat Tambahan Meninggal Dunia karena Kecelakaan | B24: tambahan 100% UP awal | C24: N/A | F24: 26 | G24: =G23-J23 -> 905625000 | H24: =H23 -> 550000000
F25: . | G25: . | H25: .
A26: Manfaat Terminal Illness | B26: 20% UP hingga maks. Rp3 bio | F26: 31 | G26: =G24 -> 905625000 | H26: =H24 -> 550000000
A27: Manfaat Hidup | B27: 50% ROP (dibayarkan pada Tahun Polis ke-15 atau Usia Tertanggung 60 tahun, mana yang lebih akhir) | C27: Berupa ROP yang dibayarkan pada Tanggal Akhir Asuransi sebesar: Apabila Peserta memenuhi "Persyaratan Yang Ditentukan", maka akan dibayarkan 2x dari percentage di atas. Namun Peserta dapat melakukan penarikan manfaat dari Dana Tanahud, dengan ketentuan sbb: Note: - Jumlah Penarikan Dana Tanahud tidak boleh melebihi Nilai Manfaat Hidup - Penarikan Dana Tanahud akan mengurangi Manfaat Hidup namun tidak mengurani Manfaat Meninggal Dunia. | F27: . | G27: . | H27: .
F28: 35 | G28: =G26 -> 905625000 | H28: =1.2*J7 -> 600000000
F29: . | G29: . | H29: .
F30: 45 | G30: =G28 -> 905625000 | H30: =1.3*J7 -> 650000000
F31: . | G31: . | H31: .
F32: 64 | G32: =G30 -> 905625000 | H32: =1.5*J7 -> 750000000 | M32: =G32 -> 905625000
F33: 65 | H33: =H32 -> 750000000
F34: . | H34: .
F35: 85 | H35: =H33 -> 750000000 | O35: =J9-L23 -> 58536000
F37: Summary
F39: 1. Secara total Premi, Heritage+ lebih murah 3% dibandingkan AlliSya Legacy Max. 2. Benefit yang ditawarkan Heritage+ lebih lengkap yaitu terdapat Manfaat TI, Manfaat Tambahan MD karena Kecelakaan, dan MCU, yang mana tidak dimiliki oleh produk AlliSya Legacy Max 3. Secara benefit MD yang didapatkan di produk Heritage+ lebih tinggi karena percentage kenaikan hingga 200%, sedangkan kenaikan AlliSya maks. 150%, dengan kenaikan 10% setiap 10 tahun yang dimulai dari tahun Polis ke-15 atau ke-25, sesuai dgn Usia Masuk. 4. Untuk Manfaat Akhir Masa Pertanggungan, Heritage+ lebih unggul karena berupa 200% UP sedangkan AlliSya Legacy Max nilainya sama dengan Manfaat Hidup. Conclusion: Secara keseluruhan, Heritage+ lebih unggul dibandingkan AlliSya Legacy Max.
A42: Manfaat Pemeriksaan Kesehatan | B42: Rp 2 mio / USD 125 | C42: N/A
A43: Manfaat Akhir Masa Pertanggungan | B43: 200% UP dikurangi Manfaat Hidup dan manfaat TI yang sudah dibayarkan (jika ada) | C43: Sebesar Nilai Manfaat Hidup dikurangi Penarikan Dana Tanahud (jika ada)
A44: Asuransi Tambahan (Riders) | B44: - Payor Benefit Plus - Waiver of Premium Plus | C44: No Info
...

Sheet Premi H+ 2 bio
A1: Single Premium (Without Living Benefit) | G1: 2 Years Premium (Without Living Benefit) | M1: 5 Years Premium (Without Living Benefit) | S1: 10 Years Premium (Without Living Benefit) | Y1: Single Premium (With Living Benefit ROP50) | AE1: 2 Years Premium (With Living Benefit ROP50) | AK1: 5 Years Premium (With Living Benefit ROP50) | AQ1: 10 Years Premium (With Living Benefit ROP50) | AX1: 15 Years Premium (Without Living Benefit ROP50)
A2: Premium Table | G2: Premium Table | M2: Premium Table | S2: Premium Table | Y2: Premium Table | AE2: Premium Table | AK2: Premium Table | AQ2: Premium Table | AX2: Premium Table
A3: Single Premium (Without Living Benefit) | B3: MALE | D3: FEMALE | G3: 66 | H3: MALE | J3: FEMALE | M3: 66 | N3: MALE | P3: FEMALE | S3: 66 | T3: MALE | V3: FEMALE | Y3: 66 | Z3: MALE | AB3: FEMALE | AE3: 66 | AF3: MALE | AH3: FEMALE | AK3: 66 | AL3: MALE | AN3: FEMALE | AQ3: 66 | AR3: MALE | AT3: FEMALE | AX3: 66 | AY3: MALE | BA3: FEMALE
A4: Age Last | B4: NS | D4: NS | G4: Age Last | H4: NS | J4: NS | M4: Age Last | N4: NS | P4: NS | S4: Age Last | T4: NS | V4: NS | Y4: Age Last | Z4: NS | AB4: NS | AE4: Age Last | AF4: NS | AH4: NS | AK4: Age Last | AL4: NS | AN4: NS | AQ4: Age Last | AR4: NS | AT4: NS | AX4: Age Last | AY4: NS | BA4: NS
A5: 0 | B5: 65.41 | D5: 53.57 | G5: 0 | H5: 35.3 | J5: 29.11 | M5: 0 | N5: 15.17 | P5: 12.53 | S5: 0 | T5: 8.02 | V5: 6.6 | Y5: 0 | Z5: 66.35 | AB5: 54.42 | AE5: 0 | AF5: 35.94 | AH5: 29.68 | AK5: 0 | AL5: 15.44 | AN5: 12.78 | AQ5: 0 | AR5: 8.18 | AT5: 6.74 | AX5: 0 | AY5: 5.83 | BA5: 4.85
A6: 1 | B6: 67.93 | D6: 55.6 | G6: 1 | H6: 36.61 | J6: 30.16 | M6: 1 | N6: 15.72 | P6: 12.97 | S6: 1 | T6: 8.31 | V6: 6.83 | Y6: 1 | Z6: 69.01 | AB6: 56.47 | AE6: 1 | AF6: 37.32 | AH6: 30.76 | AK6: 1 | AL6: 16.03 | AN6: 13.23 | AQ6: 1 | AR6: 8.49 | AT6: 6.97 | AX6: 1 | AY6: 6.03 | BA6: 5.01
A7: 2 | B7: 70.62 | D7: 57.72 | G7: 2 | H7: 38.03 | J7: 31.24 | M7: 2 | N7: 16.32 | P7: 13.44 | S7: 2 | T7: 8.63 | V7: 7.07 | Y7: 2 | Z7: 71.85 | AB7: 58.71 | AE7: 2 | AF7: 38.84 | AH7: 31.91 | AK7: 2 | AL7: 16.68 | AN7: 13.73 | AQ7: 2 | AR7: 8.84 | AT7: 7.24 | AX7: 2 | AY7: 6.27 | BA7: 5.19
A8: 3 | B8: 73.33 | D8: 59.86 | G8: 3 | H8: 39.45 | J8: 32.36 | M8: 3 | N8: 16.93 | P8: 13.92 | S8: 3 | T8: 8.95 | V8: 7.32 | Y8: 3 | Z8: 74.69 | AB8: 60.93 | AE8: 3 | AF8: 40.34 | AH8: 33.09 | AK8: 3 | AL8: 17.31 | AN8: 14.23 | AQ8: 3 | AR8: 9.18 | AT8: 7.5 | AX8: 3 | AY8: 6.5 | BA8: 5.37
A9: 4 | B9: 76.1 | D9: 62.09 | G9: 4 | H9: 40.91 | J9: 33.54 | M9: 4 | N9: 17.55 | P9: 14.41 | S9: 4 | T9: 9.27 | V9: 7.58 | Y9: 4 | Z9: 77.57 | AB9: 63.19 | AE9: 4 | AF9: 41.87 | AH9: 34.28 | AK9: 4 | AL9: 17.96 | AN9: 14.74 | AQ9: 4 | AR9: 9.52 | AT9: 7.77 | AX9: 4 | AY9: 6.72 | BA9: 5.56
A10: 5 | B10: 78.9 | D10: 64.33 | G10: 5 | H10: 42.38 | J10: 34.71 | M10: 5 | N10: 18.16 | P10: 14.91 | S10: 5 | T10: 9.6 | V10: 7.84 | Y10: 5 | Z10: 80.5 | AB10: 65.55 | AE10: 5 | AF10: 43.42 | AH10: 35.53 | AK10: 5 | AL10: 18.62 | AN10: 15.27 | AQ10: 5 | AR10: 9.86 | AT10: 8.04 | AX10: 5 | AY10: 6.95 | BA10: 5.73
A11: 6 | B11: 81.8 | D11: 66.63 | G11: 6 | H11: 43.89 | J11: 35.91 | M11: 6 | N11: 18.8 | P11: 15.42 | S11: 6 | T11: 9.93 | V11: 8.1 | Y11: 6 | Z11: 83.55 | AB11: 68.06 | AE11: 6 | AF11: 45.04 | AH11: 36.86 | AK11: 6 | AL11: 19.3 | AN11: 15.83 | AQ11: 6 | AR11: 10.22 | AT11: 8.33 | AX11: 6 | AY11: 7.18 | BA11: 5.93
A12: 7 | B12: 84.9 | D12: 69.05 | G12: 7 | H12: 45.52 | J12: 37.18 | M12: 7 | N12: 19.49 | P12: 15.95 | S12: 7 | T12: 10.3 | V12: 8.42 | Y12: 7 | Z12: 86.8 | AB12: 70.69 | AE12: 7 | AF12: 46.76 | AH12: 38.26 | AK12: 7 | AL12: 20.02 | AN12: 16.42 | AQ12: 7 | AR12: 10.6 | AT12: 8.69 | AX12: 7 | AY12: 7.42 | BA12: 6.12
A13: 8 | B13: 88.17 | D13: 71.58 | G13: 8 | H13: 47.24 | J13: 38.5 | M13: 8 | N13: 20.21 | P13: 16.51 | S13: 8 | T13: 10.68 | V13: 8.72 | Y13: 8 | Z13: 90.24 | AB13: 73.45 | AE13: 8 | AF13: 48.59 | AH13: 39.72 | AK13: 8 | AL13: 20.79 | AN13: 17.04 | AQ13: 8 | AR13: 11.02 | AT13: 9.02 | AX13: 8 | AY13: 7.69 | BA13: 6.32
A14: 9 | B14: 91.61 | D14: 74.32 | G14: 9 | H14: 49.04 | J14: 39.94 | M14: 9 | N14: 20.96 | P14: 17.11 | S14: 9 | T14: 11.08 | V14: 9.04 | Y14: 9 | Z14: 93.86 | AB14: 76.36 | AE14: 9 | AF14: 50.51 | AH14: 41.26 | AK14: 9 | AL14: 21.6 | AN14: 17.68 | AQ14: 9 | AR14: 11.45 | AT14: 9.37 | AX14: 9 | AY14: 7.97 | BA14: 6.54
A15: 10 | B15: 95.21 | D15: 77.21 | G15: 10 | H15: 50.94 | J15: 41.46 | M15: 10 | N15: 21.76 | P15: 17.75 | S15: 10 | T15: 11.5 | V15: 9.37 | Y15: 10 | Z15: 97.68 | AB15: 79.42 | AE15: 10 | AF15: 52.54 | AH15: 42.89 | AK15: 10 | AL15: 22.46 | AN15: 18.37 | AQ15: 10 | AR15: 11.9 | AT15: 9.73 | AX15: 10 | AY15: 8.27 | BA15: 6.78
A16: 11 | B16: 98.99 | D16: 80.25 | G16: 11 | H16: 52.92 | J16: 43.05 | M16: 11 | N16: 22.6 | P16: 18.42 | S16: 11 | T16: 11.95 | V16: 9.73 | Y16: 11 | Z16: 101.67 | AB16: 82.66 | AE16: 11 | AF16: 54.67 | AH16: 44.61 | AK16: 11 | AL16: 23.36 | AN16: 19.1 | AQ16: 11 | AR16: 12.38 | AT16: 10.12 | AX16: 11 | AY16: 8.58 | BA16: 7.03
... A54: 49 | B54: 440.93 | D54: 373.23 | G54: 49 | H54: 241.18 | J54: 198.74 | M54: 49 | N54: 99.74 | P54: 84.22 | S54: 49 | T54: 54.61 | V54: 45.75 | Y54: 49 | Z54: 485.73 | AB54: 421.7 | AE54: 49 | AF54: 304.54 | AH54: 253.2 | AK54: 49 | AL54: 113.31 | AN54: 98.34 | AQ54: 49 | AR54: 64.65 | AT54: 55.62 | AX54: 49 | AY54: 40.78 | BA54: 33.81
A55: 50 | B55: 455.77 | D55: 386.94 | G55: 50 | H55: 252.34 | J55: 206.2 | M55: 50 | N55: 103.23 | P55: 87.36 | S55: 50 | T55: 56.64 | V55: 47.55 | Y55: 50 | Z55: 498.54 | AB55: 434.2 | AE55: 50 | AF55: 315.31 | AH55: 263.18 | AJ55: 92760000 | AK55: 50 | AL55: 116.36 | AN55: 101.25 | AQ55: 50 | AR55: 66.51 | AT55: 57.36 | AX55: 50 | AY55: 42.4 | BA55: 35.18
A56: 51 | B56: 470.81 | D56: 400.96 | G56: 51 | H56: 263.87 | J56: 213.77 | M56: 51 | N56: 106.78 | P56: 90.58 | S56: 51 | T56: 58.75 | V56: 49.41 | Y56: 51 | Z56: 511.28 | AB56: 446.76 | AE56: 51 | AF56: 326.15 | AH56: 273.31 | AK56: 51 | AL56: 119.4 | AN56: 104.18 | AQ56: 51 | AR56: 68.35 | AT56: 59.11 | AX56: 51 | AY56: 44.05 | BA56: 36.61
A57: 52 | B57: 485.97 | D57: 415.26 | G57: 52 | H57: 275.63 | J57: 223.03 | M57: 52 | N57: 110.36 | P57: 93.88 | S57: 52 | T57: 60.87 | V57: 51.32 | Y57: 52 | Z57: 523.75 | AB57: 459.3 | AE57: 52 | AF57: 336.91 | AH57: 283.57 | AK57: 52 | AL57: 122.38 | AN57: 107.11 | AQ57: 52 | AR57: 70.18 | AT57: 60.87 | AX57: 52 | AY57: 45.74 | BA57: 38.08
A58: 53 | B58: 501.29 | D58: 429.85 | G58: 53 | H58: 287.69 | J58: 233.77 | M58: 53 | N58: 113.98 | P58: 97.22 | S58: 53 | T58: 63.04 | V58: 53.27 | Y58: 53 | Z58: 536.24 | AB58: 471.82 | AE58: 53 | AF58: 347.79 | AH58: 293.99 | AK58: 53 | AL58: 125.36 | AN58: 110.06 | AQ58: 53 | AR58: 72.03 | AT58: 62.63 | AX58: 53 | AY58: 47.47 | BA58: 39.61
A59: 54 | B59: 516.68 | D59: 444.69 | G59: 54 | H59: 300.01 | J59: 244.86 | M59: 54 | N59: 117.63 | P59: 100.69 | S59: 54 | T59: 65.23 | V59: 55.28 | Y59: 54 | Z59: 548.68 | AB59: 484.36 | AE59: 54 | AF59: 358.7 | AH59: 304.5 | AK59: 54 | AL59: 128.34 | AN59: 112.95 | AQ59: 54 | AR59: 73.88 | AT59: 64.39 | AX59: 54 | AY59: 49.21 | BA59: 41.17
A60: 55 | B60: 532.34 | D60: 459.76 | G60: 55 | H60: 312.72 | J60: 256.32 | M60: 55 | N60: 121.29 | P60: 104.21 | S60: 55 | T60: 67.48 | V60: 57.31 | Y60: 55 | Z60: 561.13 | AB60: 496.88 | AE60: 55 | AF60: 369.73 | AH60: 315.11 | AK60: 55 | AL60: 131.33 | AN60: 115.9 | AQ60: 55 | AR60: 75.75 | AT60: 66.16 | AX60: 55 | AY60: 51.04 | BA60: 42.77
A61: 56 | B61: 548.17 | D61: 475.07 | G61: 56 | H61: 325.81 | J61: 268.18 | M61: 56 | N61: 125.1 | P61: 107.81 | S61: 56 | T61: 69.78 | V61: 59.41 | Y61: 56 | Z61: 573.57 | AB61: 509.41 | AE61: 56 | AF61: 380.89 | AH61: 325.86 | AK61: 56 | AL61: 134.3 | AN61: 118.85 | AQ61: 56 | AR61: 77.63 | AT61: 67.9 | AX61: 56 | AY61: 52.93 | BA61: 44.42
A62: 57 | B62: 564.04 | D62: 490.54 | G62: 57 | H62: 339.11 | J62: 280.29 | M62: 57 | N62: 128.91 | P62: 111.4 | S62: 57 | T62: 72.1 | V62: 61.52 | Y62: 57 | Z62: 585.86 | AB62: 521.77 | AE62: 57 | AF62: 391.97 | AH62: 336.54 | AK62: 57 | AL62: 137.27 | AN62: 121.73 | AQ62: 57 | AR62: 79.5 | AT62: 69.65 | AX62: 57 | AY62: 54.85 | BA62: 46.11
A63: 58 | B63: 579.97 | D63: 506.24 | G63: 58 | H63: 352.69 | J63: 292.78 | M63: 58 | N63: 132.74 | P63: 115.05 | S63: 58 | T63: 74.43 | V63: 63.68 | Y63: 58 | Z63: 598.14 | AB63: 534.2 | AE63: 58 | AF63: 403.13 | AH63: 347.38 | AK63: 58 | AL63: 140.23 | AN63: 124.62 | AQ63: 58 | AR63: 81.37 | AT63: 71.43 | AX63: 58 | AY63: 56.83 | BA63: 47.83
A64: 59 | B64: 595.92 | D64: 522.07 | G64: 59 | H64: 366.54 | J64: 305.59 | M64: 59 | N64: 136.59 | P64: 118.75 | S64: 59 | T64: 76.84 | V64: 65.88 | Y64: 59 | Z64: 610.45 | AB64: 546.65 | AE64: 59 | AF64: 414.42 | AH64: 358.35 | AK64: 59 | AL64: 144.42 | AN64: 127.53 | AQ64: 59 | AR64: 83.32 | AT64: 73.23 | AX64: 59 | AY64: 58.87 | BA64: 49.62
A65: 60 | B65: 611.88 | D65: 538.17 | G65: 60 | H65: 380.65 | J65: 318.85 | M65: 60 | N65: 140.48 | P65: 122.48 | S65: 60 | T65: 79.31 | V65: 68.15 | Y65: 60 | Z65: 622.83 | AB65: 559.15 | AE65: 60 | AF65: 425.75 | AH65: 369.47 | AK65: 60 | AL65: 148.76 | AN65: 130.4 | AQ65: 60 | AR65: 85.29 | AT65: 75.06 | AX65: 60 | AY65: 60.97 | BA65: 51.49
A66: 61 | B66: 627.77 | D66: 554.42 | G66: 61 | H66: 394.99 | J66: 332.47 | M66: 61 | N66: 144.35 | P66: 126.33 | S66: 61 | T66: 81.82 | V66: 70.48 | Y66: 61 | Z66: 635.23 | AB66: 571.72 | AE66: 61 | AF66: 437.19 | AH66: 380.74 | AK66: 61 | AL66: 153.19 | AN66: 133.4 | AQ66: 61 | AR66: 87.47 | AT66: 76.93 | AX66: 61
